<?xml version="1.0" ?>
<robot name="landing_gear" xmlns:xacro="http://ros.org/wiki/xacro">
    <!-- <xacro:property name="link1_length" value="0.2"/>
    <xacro:property name="link1_radius" value="0.02"/> -->
<xacro:property name="base_r" value="0.2"/>
<xacro:property name="base_d" value="0.002"/>

<!-- Base Link -->    
<link name="base_link">
    <origin xyz="0 0 0" rpy="0 0 0"/>
        <inertial>
            <mass value="0.1"/>
            <inertia ixx="0.001" ixy="0.0" ixz="0.0" iyy="0.001" iyz="0.0" izz="0.001"/>
        </inertial>
</link>

<joint name="base_link_connection" type="fixed">
    <parent link="base_link"/>
    <child link="base"/>
    <origin xyz="0 0 0" rpy="1.5714 0 0"/>
    <axis xyz="1 0 0"/>
</joint>

<link name="base">
        <visual>
            <origin rpy="0 0 0" xyz="0.01 -0.01 0" />
            <geometry>
                <mesh filename="package://landing_gear_description/meshes/base.stl" scale="0.001 0.001 0.001"/>
            </geometry>
        </visual>
        <collision>
            <origin rpy="0 0 0" xyz="0.01 -0.01 0" />
            <geometry>
                <mesh filename="package://landing_gear_description/meshes/base.stl" scale="0.001 0.001 0.001"/>
            </geometry>
        </collision>
        <inertial>
            <origin xyz="-0.01 0 0" rpy="0 0 0"/>
            <mass value="0.1"/>
            <inertia ixx="0.001" ixy="0.0" ixz="0.0" iyy="0.001" iyz="0.0" izz="0.001"/>
        </inertial>
</link>

<!-- leg 1 -->
<link name="leg">
    <visual>
        <origin rpy="0 0 0" xyz="0 -0.136 -0.017" />
        <geometry>
            <mesh filename="package://landing_gear_description/meshes/link1.stl" scale="0.001 0.001 0.001"/>
        </geometry>
    </visual>
    <collision>
        <origin rpy="0 0 0" xyz="0 -0.136 -0.017" />
        <geometry>
            <mesh filename="package://landing_gear_description/meshes/link1.stl" scale="0.001 0.001 0.001"/>
        </geometry>
    </collision>
    <inertial>
        <origin rpy="0 0 0" xyz="0 0 0" />
        <mass value="0.1"/>
        <inertia ixx="0.001" ixy="0.0" ixz="0.0" iyy="0.001" iyz="0.0" izz="0.001"/>
    </inertial>
</link>


<joint name="base_leg_joint" type="revolute">
    <parent link="base"/>
    <child link="leg"/>
    <!-- the link 1 rotated  ni x rad-->
    <origin xyz="0 0 -0.1" rpy="-1.5714 3.1415 0"/>
    <axis xyz="-1 0 0"/>
    <limit effort="100" velocity="1" lower="-1.5714" upper="1.5714"/>
</joint>

<link name="link2_leg">
    <visual>
        <origin rpy="0 0 0" xyz="0.01 0.0125 -0.0125" />
        <geometry>
            <mesh filename="package://landing_gear_description/meshes/link2.stl" scale="0.001 0.001 0.001"/>
        </geometry>
    </visual>
    <collision>
        <origin rpy="0 0 0" xyz="0.01 0.0125 -0.0125" />
        <geometry>
            <mesh filename="package://landing_gear_description/meshes/link2.stl" scale="0.001 0.001 0.001"/>
        </geometry>
    </collision>
    <inertial>
        <origin rpy="0 0 0" xyz="0 0 0" />
        <mass value="0.1"/>
        <inertia ixx="0.001" ixy="0.0" ixz="0.0" iyy="0.001" iyz="0.0" izz="0.001"/>
    </inertial>
</link>

<joint name="base_link2_leg_joint" type="revolute">
    <parent link="leg"/>
    <child link="link2_leg"/>
    <origin xyz="0 -0.12 0" rpy="-1.5714 0 0"/>
    <axis xyz="1 0 0"/>
    <limit effort="1000" velocity="1" lower="-3.1415" upper="3.1415"/>
</joint>

<!-- leg 2 -->
<link name="leg_2">
    <visual>
        <origin rpy="0 0 0" xyz="0 -0.136 -0.017" />
        <geometry>
            <mesh filename="package://landing_gear_description/meshes/link1.stl" scale="0.001 0.001 0.001"/>
        </geometry>
    </visual>
    <collision>
        <origin rpy="0 0 0" xyz="0 -0.136 -0.017" />
        <geometry>
            <mesh filename="package://landing_gear_description/meshes/link1.stl" scale="0.001 0.001 0.001"/>
        </geometry>
    </collision>
    <inertial>
        <origin rpy="0 0 0" xyz="0 0 0" />
        <mass value="0.1"/>
        <inertia ixx="0.001" ixy="0.0" ixz="0.0" iyy="0.001" iyz="0.0" izz="0.001"/>
    </inertial>
</link>


<joint name="base_leg_2_joint" type="revolute">
    <parent link="base"/>
    <child link="leg_2"/>
    <!-- the link 1 rotated  ni x rad-->
    <origin xyz="0.082 0 0.037" rpy="-1.5714 1.0475 0"/>
    <axis xyz="-1 0 0"/>
    <limit effort="100" velocity="1" lower="-1.5714" upper="1.5714"/>
</joint>

<link name="link2_leg_2">
    <visual>
        <origin rpy="0 0 0" xyz="0.01 0.0125 -0.0125" />
        <geometry>
            <mesh filename="package://landing_gear_description/meshes/link2.stl" scale="0.001 0.001 0.001"/>
        </geometry>
    </visual>
    <collision>
        <origin rpy="0 0 0" xyz="0.01 0.0125 -0.0125" />
        <geometry>
            <mesh filename="package://landing_gear_description/meshes/link2.stl" scale="0.001 0.001 0.001"/>
        </geometry>
    </collision>
    <inertial>
        <origin rpy="0 0 0" xyz="0 0 0" />
        <mass value="0.1"/>
        <inertia ixx="0.001" ixy="0.0" ixz="0.0" iyy="0.001" iyz="0.0" izz="0.001"/>
    </inertial>
</link>

<joint name="base_link2_leg_2_joint" type="revolute">
    <parent link="leg_2"/>
    <child link="link2_leg_2"/>
    <origin xyz="0 -0.12 0" rpy="-1.5714 0 0"/>
    <axis xyz="1 0 0"/>
    <limit effort="1000" velocity="1" lower="-1.5714" upper="1.5714"/>
</joint>

<!-- leg 3 -->
<link name="leg_3">
    <visual>
        <origin rpy="0 0 0" xyz="0 -0.136 -0.017" />
        <geometry>
            <mesh filename="package://landing_gear_description/meshes/link1.stl" scale="0.001 0.001 0.001"/>
        </geometry>
    </visual>
    <collision>
        <origin rpy="0 0 0" xyz="0 -0.136 -0.017" />
        <geometry>
            <mesh filename="package://landing_gear_description/meshes/link1.stl" scale="0.001 0.001 0.001"/>
        </geometry>
    </collision>
    <inertial>
        <origin rpy="0 0 0" xyz="0 0 0" />
        <mass value="0.1"/>
        <inertia ixx="0.001" ixy="0.0" ixz="0.0" iyy="0.001" iyz="0.0" izz="0.001"/>
    </inertial>
</link>


<joint name="base_leg_3_joint" type="revolute">
    <parent link="base"/>
    <child link="leg_3"/>
    <!-- the link 1 rotated  ni x rad-->
    <origin xyz="-0.082 0 0.037" rpy="-1.5714 -1.0475 0"/>
    <axis xyz="-1 0 0"/>
    <limit effort="100" velocity="1" lower="-1.5714" upper="1.5714"/>
</joint>

<link name="link2_leg_3">
    <visual>
        <origin rpy="0 0 0" xyz="0.01 0.0125 -0.0125" />
        <geometry>
            <mesh filename="package://landing_gear_description/meshes/link2.stl" scale="0.001 0.001 0.001"/>
        </geometry>
    </visual>
    <collision>
        <origin rpy="0 0 0" xyz="0.01 0.0125 -0.0125" />
        <geometry>
            <mesh filename="package://landing_gear_description/meshes/link2.stl" scale="0.001 0.001 0.001"/>
        </geometry>
    </collision>
    <inertial>
        <origin rpy="0 0 0" xyz="0 0 0" />
        <mass value="0.1"/>
        <inertia ixx="0.001" ixy="0.0" ixz="0.0" iyy="0.001" iyz="0.0" izz="0.001"/>
    </inertial>
</link>

<joint name="base_link2_leg_3_joint" type="revolute">
    <parent link="leg_3"/>
    <child link="link2_leg_3"/>
    <origin xyz="0 -0.12 0" rpy="-1.5714 0 0"/>
    <axis xyz="1 0 0"/>
    <limit effort="1000" velocity="1" lower="-1.5714" upper="1.5714"/>
</joint>


<gazebo reference="base_link" >
    <material> Gazebo/Blue </material>
    <kinematic> true </kinematic>
</gazebo>


<!-- motor controller -->
<gazebo>
    <plugin name="gazebo_ros_control" filename="libgazebo_ros_control.so">
        <robotNamespace>landing_gear</robotNamespace>
    </plugin>
</gazebo>

<!-- leg 1 controller -->

<transmission name="leg_transmission">
    <type>transmission_interfacec/SimpleTransmission</type>
    <actuator name="motor1">
        <mechanicalReduction>1</mechanicalReduction>
    </actuator>
    <joint name="base_leg_joint">
        <hardwareInterface>hardware_interface/EffortJointInterface</hardwareInterface>
    </joint>
</transmission>

<transmission name="leg_1_2_transmission">
    <type>transmission_interfacec/SimpleTransmission</type>
    <actuator name="motor1_2">
        <mechanicalReduction>1</mechanicalReduction>
    </actuator>
    <joint name="base_link2_leg_joint">
        <hardwareInterface>hardware_interface/EffortJointInterface</hardwareInterface>
    </joint>
</transmission>

<transmission name="leg_2_transmission">
    <type>transmission_interfacec/SimpleTransmission</type>
    <actuator name="motor2">
        <mechanicalReduction>1</mechanicalReduction>
    </actuator>
    <joint name="base_leg_2_joint">
        <hardwareInterface>hardware_interface/EffortJointInterface</hardwareInterface>
    </joint>
</transmission>
<transmission name="leg_2_2_transmission">
    <type>transmission_interfacec/SimpleTransmission</type>
    <actuator name="motor2_2">
        <mechanicalReduction>1</mechanicalReduction>
    </actuator>
    <joint name="base_link2_leg_2_joint">
        <hardwareInterface>hardware_interface/EffortJointInterface</hardwareInterface>
    </joint>
</transmission>

<transmission name="leg_3_transmission">
    <type>transmission_interfacec/SimpleTransmission</type>
    <actuator name="motor3">
        <mechanicalReduction>1</mechanicalReduction>
    </actuator>
    <joint name="base_leg_3_joint">
        <hardwareInterface>hardware_interface/EffortJointInterface</hardwareInterface>
    </joint>
</transmission>
<transmission name="leg_3_2_transmission">
    <type>transmission_interfacec/SimpleTransmission</type>
    <actuator name="motor3_2">
        <mechanicalReduction>1</mechanicalReduction>
    </actuator>
    <joint name="base_link2_leg_3_joint">
        <hardwareInterface>hardware_interface/EffortJointInterface</hardwareInterface>
    </joint>
</transmission>

</robot>