<?xml version="1.0" ?>
<robot name="landing_gear_leg" xmlns:xacro="http://ros.org/wiki/xacro">

<xacro:macro name="leg" params="postfix x y z R P Y ">

<!-- LINK 1 -->
    <link name="leg_${postfix}">
        <visual>
            <origin rpy="0 0 0" xyz="0 -0.136 -0.017" />
            <geometry>
                <mesh filename="package://landing_gear_description/meshes/link1.stl" scale="0.001 0.001 0.001"/>
            </geometry>
        </visual>
        <collision>
            <origin rpy="0 0 0" xyz="0 -0.136 -0.017" />
            <geometry>
                <mesh filename="package://landing_gear_description/meshes/link1.stl" scale="0.001 0.001 0.001"/>
            </geometry>
        </collision>
        <inertial>
            <origin rpy="0 0 0" xyz="0 0 0" />
            <mass value="0.1"/>
            <inertia ixx="0.001" ixy="0.0" ixz="0.0" iyy="0.001" iyz="0.0" izz="0.001"/>
        </inertial>
    </link>

<!-- Base to LINK1 -->
    <joint name="base_leg_${postfix}_joint" type="revolute">
        <parent link="base"/>
        <child link="leg_${postfix}"/>
        <!-- the link 1 rotated  ni x rad-->
        <origin xyz="${x} ${y} ${z}" rpy="${R} ${P} ${Y}"/>
        <axis xyz="-1 0 0"/>
        <limit effort="100" velocity="1" lower="-1.5714" upper="1.5714"/>
    </joint>

<!-- LINK2 -->
    <link name="link2_leg_${postfix}">
        <visual>
            <origin rpy="0 0 0" xyz="0.01 0.0125 -0.0125" />
            <geometry>
                <mesh filename="package://landing_gear_description/meshes/link2.stl" scale="0.001 0.001 0.001"/>
            </geometry>
        </visual>
        <collision>
            <origin rpy="0 0 0" xyz="0.01 0.0125 -0.0125" />
            <geometry>
                <mesh filename="package://landing_gear_description/meshes/link2.stl" scale="0.001 0.001 0.001"/>
            </geometry>
            <surface>
                <contact>
                <ode/>
                </contact>
                <friction>
                <ode/>
                <torsional>
                    <ode/>
                </torsional>
                </friction>
                <bounce restitution_coefficient="1.0" threshold="0.01"/>
            </surface>
        </collision>
        <inertial>
            <origin rpy="0 0 0" xyz="0 0 0" />
            <mass value="0.1"/>
            <inertia ixx="0.001" ixy="0.0" ixz="0.0" iyy="0.001" iyz="0.0" izz="0.001"/>
        </inertial>
    </link>
<!-- LINK1 to LINK2 -->
    <joint name="base_link2_leg_${postfix}_joint" type="revolute">
        <parent link="leg_${postfix}"/>
        <child link="link2_leg_${postfix}"/>
        <origin xyz="0 -0.12 0" rpy="-1.5714 0 0"/>
        <axis xyz="1 0 0"/>
        <limit effort="100" velocity="1" lower="-3.1415" upper="3.1415"/>
    </joint>

<!-- Base to LINK1 Transmission -->
    <transmission name="leg_${postfix}_transmission">
        <type>transmission_interfacec/SimpleTransmission</type>
        <actuator name="motor${postfix}">
            <mechanicalReduction>1</mechanicalReduction>
        </actuator>
        <joint name="base_leg_${postfix}_joint">
            <hardwareInterface>hardware_interface/EffortJointInterface</hardwareInterface>
        </joint>
    </transmission>

<!-- LINK1 to LINK2 Transmission -->
    <transmission name="leg_${postfix}_2_transmission">
        <type>transmission_interfacec/SimpleTransmission</type>
        <actuator name="motor${postfix}_2">
            <mechanicalReduction>1</mechanicalReduction>
        </actuator>
        <joint name="base_link2_leg_${postfix}_joint">
            <hardwareInterface>hardware_interface/EffortJointInterface</hardwareInterface>
        </joint>
    </transmission>

<!-- lidar sensor link-->
<link name="base_scan_${postfix}">
    <origin rpy="0 0 0" xyz="0 0 0" />
    <inertial>
        <origin xyz="0.0 0.0 0.0" rpy="0.0 0.0 0.0"/>
        <mass value="0.0001"/>
        <inertia ixx="1" ixy="0.0" ixz="0" iyy="1" iyz="0.0" izz="1"/>
    </inertial>
</link>
<joint name="scan_joint_${postfix}" type="fixed">
    <parent link="link2_leg_${postfix}"/>
    <child link="base_scan_${postfix}"/>
    <origin xyz="0 0.05 0" rpy="0 0 1.57"/>
    <axis xyz="1 0 0"/>
</joint>
<!-- lidar sensor gazebo plugin-->
<gazebo reference="base_scan_${postfix}">
    <gravity>true</gravity>
    <sensor type="ray" name="laser_scan_${postfix}">
        <pose>0 0 0 0 0 0</pose>
        <visualize>true</visualize>
        <always_on>true</always_on>
        <update_rate>5</update_rate>
        <ray>
            <scan>
            <horizontal>
              <samples>1</samples>
              <resolution>1</resolution>    
              
            </horizontal>
            </scan>
            <range>
                <min>0.01</min>
                <max>2</max>
                <resolution>0.015</resolution>
            </range>
            <noise>
                <type>gaussian</type>
                <mean>0.0</mean>
                <stddev>0.0</stddev>
            </noise>
        </ray>
        <plugin name="gazebo_ros_scan_controller" filename="libgazebo_ros_laser.so">
            <robotNamespace>lg</robotNamespace>
            <topicName>lidar${postfix}</topicName>
            <frameName>base_scan_${postfix}</frameName>
        </plugin>      
    </sensor>
    </gazebo>

</xacro:macro>
</robot>
